<?xml version="1.0" encoding="utf-8"?>
<!-- This URDF was automatically created by SolidWorks to URDF Exporter! Originally created by Stephen Brawner (brawner@gmail.com) 
     Commit Version: 1.6.0-4-g7f85cfe  Build Version: 1.6.7995.38578
     For more information, please see http://wiki.ros.org/sw_urdf_exporter -->
<robot
  name="TUNA">
  <link
    name="base_link">
    <inertial>
      <origin
        xyz="0.69609 1.1996 1.7554"
        rpy="0 0 0" />
      <mass
        value="60.398" />
      <inertia
        ixx="2.3246"
        ixy="-0.00018391"
        ixz="-0.00054907"
        iyy="4.6684"
        iyz="-0.0053583"
        izz="2.4993" />
    </inertial>
    <visual>
      <origin
        xyz="0 0 0"
        rpy="0 0 0" />
      <geometry>
        <mesh
          filename="package://TUNA/meshes/base_link.STL" />
      </geometry>
      <material
        name="">
        <color
          rgba="0.79216 0.81961 0.93333 1" />
      </material>
    </visual>
    <collision>
      <origin
        xyz="0 0 0"
        rpy="0 0 0" />
      <geometry>
        <mesh
          filename="package://TUNA/meshes/base_link.STL" />
      </geometry>
    </collision>
  </link>
  <link
    name="spoiler1">
    <inertial>
      <origin
        xyz="0.04844 -0.0046803 0.11967"
        rpy="0 0 0" />
      <mass
        value="0.84318" />
      <inertia
        ixx="0.0044575"
        ixy="9.144E-05"
        ixz="3.8083E-05"
        iyy="0.0054363"
        iyz="1.6169E-05"
        izz="0.0011268" />
    </inertial>
    <visual>
      <origin
        xyz="0 0 0"
        rpy="0 0 0" />
      <geometry>
        <mesh
          filename="package://TUNA/meshes/spoiler1.STL" />
      </geometry>
      <material
        name="">
        <color
          rgba="0.79216 0.81961 0.93333 1" />
      </material>
    </visual>
    <collision>
      <origin
        xyz="0 0 0"
        rpy="0 0 0" />
      <geometry>
        <mesh
          filename="package://TUNA/meshes/spoiler1.STL" />
      </geometry>
    </collision>
  </link>
  <joint
    name="joint01"
    type="revolute">
    <origin
      xyz="0.97792 -1.653 1.2476"
      rpy="1.6586 0.115 1.5809" />
    <parent
      link="base_link" />
    <child
      link="spoiler1" />
    <axis
      xyz="0 0 1" />
    <limit
      lower="0.7854"
      upper="0.7854"
      effort="0.5"
      velocity="8.7" />
  </joint>
  <link
    name="airelon1">
    <inertial>
      <origin
        xyz="0.024706 -0.0035928 0.16798"
        rpy="0 0 0" />
      <mass
        value="0.34937" />
      <inertia
        ixx="0.0040197"
        ixy="1.1766E-05"
        ixz="1.6012E-05"
        iyy="0.0041281"
        iyz="1.6241E-05"
        izz="0.00012774" />
    </inertial>
    <visual>
      <origin
        xyz="0 0 0"
        rpy="0 0 0" />
      <geometry>
        <mesh
          filename="package://TUNA/meshes/airelon1.STL" />
      </geometry>
      <material
        name="">
        <color
          rgba="0.79216 0.81961 0.93333 1" />
      </material>
    </visual>
    <collision>
      <origin
        xyz="0 0 0"
        rpy="0 0 0" />
      <geometry>
        <mesh
          filename="package://TUNA/meshes/airelon1.STL" />
      </geometry>
    </collision>
  </link>
  <joint
    name="joint02"
    type="revolute">
    <origin
      xyz="1.4064 -1.6027 1.2002"
      rpy="1.659 0.14418 1.5835" />
    <parent
      link="base_link" />
    <child
      link="airelon1" />
    <axis
      xyz="0 0 1" />
    <limit
      lower="0.436"
      upper="0.436"
      effort="0.5"
      velocity="8.7" />
  </joint>
  <link
    name="spoiler2">
    <inertial>
      <origin
        xyz="0.04844 -0.0046803 0.13439"
        rpy="0 0 0" />
      <mass
        value="0.84318" />
      <inertia
        ixx="0.0044575"
        ixy="9.1441E-05"
        ixz="-3.8078E-05"
        iyy="0.0054363"
        iyz="-1.6167E-05"
        izz="0.0011268" />
    </inertial>
    <visual>
      <origin
        xyz="0 0 0"
        rpy="0 0 0" />
      <geometry>
        <mesh
          filename="package://TUNA/meshes/spoiler2.STL" />
      </geometry>
      <material
        name="">
        <color
          rgba="0.79216 0.81961 0.93333 1" />
      </material>
    </visual>
    <collision>
      <origin
        xyz="0 0 0"
        rpy="0 0 0" />
      <geometry>
        <mesh
          filename="package://TUNA/meshes/spoiler2.STL" />
      </geometry>
    </collision>
  </link>
  <joint
    name="joint03"
    type="revolute">
    <origin
      xyz="0.16163 -1.653 1.2255"
      rpy="1.4823 0.16625 1.5561" />
    <parent
      link="base_link" />
    <child
      link="spoiler2" />
    <axis
      xyz="0 0 1" />
    <limit
      lower="0.7854"
      upper="0.7854"
      effort="0.5"
      velocity="8.7" />
  </joint>
  <link
    name="airelon2">
    <inertial>
      <origin
        xyz="0.024307 -0.0035315 -0.077345"
        rpy="0 0 0" />
      <mass
        value="0.35543" />
      <inertia
        ixx="0.0040977"
        ixy="1.2239E-05"
        ixz="-1.7322E-05"
        iyy="0.0042089"
        iyz="-1.5859E-05"
        izz="0.00013076" />
    </inertial>
    <visual>
      <origin
        xyz="0 0 0"
        rpy="0 0 0" />
      <geometry>
        <mesh
          filename="package://TUNA/meshes/airelon2.STL" />
      </geometry>
      <material
        name="">
        <color
          rgba="0.79216 0.81961 0.93333 1" />
      </material>
    </visual>
    <collision>
      <origin
        xyz="0 0 0"
        rpy="0 0 0" />
      <geometry>
        <mesh
          filename="package://TUNA/meshes/airelon2.STL" />
      </geometry>
    </collision>
  </link>
  <joint
    name="joint04"
    type="revolute">
    <origin
      xyz="-0.10431 -1.6027 1.1923"
      rpy="1.4826 0.14404 1.5581" />
    <parent
      link="base_link" />
    <child
      link="airelon2" />
    <axis
      xyz="0 0 1" />
    <limit
      lower="0.436"
      upper="0.436"
      effort="0.5"
      velocity="8.7" />
  </joint>
  <link
    name="rudder">
    <inertial>
      <origin
        xyz="0.030744 6.9032E-09 0.12515"
        rpy="0 0 0" />
      <mass
        value="0.22002" />
      <inertia
        ixx="0.0017147"
        ixy="-1.1029E-10"
        ixz="0.00011219"
        iyy="0.0018008"
        iyz="3.979E-11"
        izz="9.2264E-05" />
    </inertial>
    <visual>
      <origin
        xyz="0 0 0"
        rpy="0 0 0" />
      <geometry>
        <mesh
          filename="package://TUNA/meshes/rudder.STL" />
      </geometry>
      <material
        name="">
        <color
          rgba="0.79216 0.81961 0.93333 1" />
      </material>
    </visual>
    <collision>
      <origin
        xyz="0 0 0"
        rpy="0 0 0" />
      <geometry>
        <mesh
          filename="package://TUNA/meshes/rudder.STL" />
      </geometry>
    </collision>
  </link>
  <joint
    name="joint05"
    type="revolute">
    <origin
      xyz="0.69632 -1.1374 1.2541"
      rpy="0 0 2.3499" />
    <parent
      link="base_link" />
    <child
      link="rudder" />
    <axis
      xyz="0 0 1" />
    <limit
      lower="0.524"
      upper="0.524"
      effort="0.5"
      velocity="8.7" />
  </joint>
  <link
    name="elevator1">
    <inertial>
      <origin
        xyz="0.027063 -1.5698E-07 0.1307"
        rpy="0 0 0" />
      <mass
        value="0.19012" />
      <inertia
        ixx="0.0017826"
        ixy="1.2066E-09"
        ixz="0.0001122"
        iyy="0.0018472"
        iyz="5.1022E-10"
        izz="6.8988E-05" />
    </inertial>
    <visual>
      <origin
        xyz="0 0 0"
        rpy="0 0 0" />
      <geometry>
        <mesh
          filename="package://TUNA/meshes/elevator1.STL" />
      </geometry>
      <material
        name="">
        <color
          rgba="0.79216 0.81961 0.93333 1" />
      </material>
    </visual>
    <collision>
      <origin
        xyz="0 0 0"
        rpy="0 0 0" />
      <geometry>
        <mesh
          filename="package://TUNA/meshes/elevator1.STL" />
      </geometry>
    </collision>
  </link>
  <joint
    name="joint06"
    type="revolute">
    <origin
      xyz="0.79132 -1.1531 1.1784"
      rpy="1.5708 0.31262 1.5708" />
    <parent
      link="base_link" />
    <child
      link="elevator1" />
    <axis
      xyz="0 0 1" />
    <limit
      lower="0.524"
      upper="0.524"
      effort="0.5"
      velocity="8.7" />
  </joint>
  <link
    name="elevator2">
    <inertial>
      <origin
        xyz="0.027055 1.5287E-08 0.25931"
        rpy="0 0 0" />
      <mass
        value="0.19009" />
      <inertia
        ixx="0.0017824"
        ixy="-1.1876E-11"
        ixz="-0.00011221"
        iyy="0.001847"
        iyz="-1.0024E-11"
        izz="6.8951E-05" />
    </inertial>
    <visual>
      <origin
        xyz="0 0 0"
        rpy="0 0 0" />
      <geometry>
        <mesh
          filename="package://TUNA/meshes/elevator2.STL" />
      </geometry>
      <material
        name="">
        <color
          rgba="0.79216 0.81961 0.93333 1" />
      </material>
    </visual>
    <collision>
      <origin
        xyz="0 0 0"
        rpy="0 0 0" />
      <geometry>
        <mesh
          filename="package://TUNA/meshes/elevator2.STL" />
      </geometry>
    </collision>
  </link>
  <joint
    name="joint07"
    type="revolute">
    <origin
      xyz="0.21132 -1.1531 1.1784"
      rpy="1.5708 0.82316 1.5708" />
    <parent
      link="base_link" />
    <child
      link="elevator2" />
    <axis
      xyz="0 0 1" />
    <limit
      lower="0.524"
      upper="0.524"
      effort="0.5"
      velocity="8.7" />
  </joint>
  <link
    name="propeller">
    <inertial>
      <origin
        xyz="-0.000101 0.014021 1.4977E-05"
        rpy="0 0 0" />
      <mass
        value="0.029829" />
      <inertia
        ixx="1.554E-06"
        ixy="6.9935E-10"
        ixz="2.3055E-06"
        iyy="0.0001323"
        iyz="-1.0873E-10"
        izz="0.0001314" />
    </inertial>
    <visual>
      <origin
        xyz="0 0 0"
        rpy="0 0 0" />
      <geometry>
        <mesh
          filename="package://TUNA/meshes/propeller.STL" />
      </geometry>
      <material
        name="">
        <color
          rgba="0.79216 0.81961 0.93333 1" />
      </material>
    </visual>
    <collision>
      <origin
        xyz="0 0 0"
        rpy="0 0 0" />
      <geometry>
        <mesh
          filename="package://TUNA/meshes/propeller.STL" />
      </geometry>
    </collision>
  </link>
  <joint
    name="joint08"
    type="continuous">
    <origin
      xyz="0.69632 -0.97874 1.1591"
      rpy="3.1416 -1.3738 0" />
    <parent
      link="base_link" />
    <child
      link="propeller" />
    <axis
      xyz="0 1 0" />
    <limit
      lower="0"
      upper="0"
      effort="1"
      velocity="1047" />
  </joint>
</robot>